Workbook

Sheet DATOS GENERAL
B2: ESCENARIO ORIGINAL | J2: ESCENARIO BRT | R2: ESCENARIO BRT CON TRANSPORTE | AC2: ESCENARIO BRT CON TRANSPORTE, MIGRACION AL 6% | AN2: ESCENARIO BRT CON TRANSPORTE, MIGRACION AL 12% | AY2: ESCENARIO BRT CON TRANSPORTE, MIGRACION AL 18% | BJ2: ESCENARIO BRT CON TRANSPORTE, MIGRACION AL 24%
B6: Detectores IDA | J6: Detectores IDA | R6: Detectores IDA | AC6: Detectores IDA | AN6: Detectores IDA | AY6: Detectores IDA | BJ6: Detectores IDA
C9: Intersecciones | D9: TIEMPO ESPERA | E9: LONG COLA | F9: VELOCIDAD | G9: TIEMPO VIAJE | K9: Intersecciones | L9: TIEMPO ESPERA | M9: LONG COLA | N9: VELOCIDAD | O9: TIEMPO VIAJE | S9: Intersecciones | T9: TIEMPO ESPERA | U9: LONG COLA | V9: VELOCIDAD | W9: TIEMPO VIAJE | AD9: Intersecciones | AE9: TIEMPO ESPERA | AF9: LONG COLA | AG9: VELOCIDAD | AH9: TIEMPO VIAJE | AO9: Intersecciones | AP9: TIEMPO ESPERA | AQ9: LONG COLA | AR9: VELOCIDAD | AS9: TIEMPO VIAJE | AZ9: Intersecciones | BA9: TIEMPO ESPERA | BB9: LONG COLA | BC9: VELOCIDAD | BD9: TIEMPO VIAJE | BK9: Intersecciones | BL9: TIEMPO ESPERA | BM9: LONG COLA | BN9: VELOCIDAD | BO9: TIEMPO VIAJE
C10: Salida Quiroga | D10: ='IDA ORIGINAL'!B51 -> 16.374792 | E10: ='IDA ORIGINAL'!C51 -> 65.101458 | F10: ='IDA ORIGINAL'!D51 -> 6.2702083 | K10: Salida Quiroga | L10: ='IDA BRT'!B51 -> 13.875972 | M10: ='IDA BRT'!C51 -> 50.439375 | N10: ='IDA BRT'!D51 -> 7.4043056 | S10: Salida Quiroga | T10: ='IDA BRT TRANS'!B51 -> 13.903889 | U10: ='IDA BRT TRANS'!C51 -> 50.128542 | V10: ='IDA BRT TRANS'!D51 -> 7.3726389 | Y10: =T10-(T10*0.03) -> 13.486772 | Z10: =U10-(U10*0.03) -> 48.624685 | AA10: =V10+(V10*0.03) -> 7.5938181 | AD10: Salida Quiroga | AE10: 12.952639 | AF10: 46.873542 | AG10: 7.7154167 | AJ10: =T10-(T10*0.08) -> 12.791578 | AK10: =U10-(U10*0.08) -> 46.118258 | AL10: =V10+(V10*0.08) -> 7.96245 | AO10: Salida Quiroga | AP10: 13.622222 | AQ10: 46.207083 | AR10: 7.4375 | AU10: =T10-(T10*0.14) -> 11.957344 | AV10: =U10-(U10*0.14) -> 43.110546 | AW10: =V10+(V10*0.14) -> 8.4048083 | AZ10: Salida Quiroga | BA10: 12.843403 | BB10: 42.291528 | BC10: 7.8347222 | BF10: =T10-(T10*0.2) -> 11.123111 | BG10: =U10-(U10*0.2) -> 40.102833 | BH10: =V10+(V10*0.2) -> 8.8471667 | BK10: Salida Quiroga | BL10: 12.265625 | BM10: 39.353819 | BN10: 8.1029861 | BO10: 2294.06
B11: PRINCIPAL | C11: San Juanito | D11: ='IDA ORIGINAL'!B85 -> 26.159583 | E11: ='IDA ORIGINAL'!C86 -> 104.12687 | F11: ='IDA ORIGINAL'!D86 -> 6.3894792 | J11: PRINCIPAL | K11: San Juanito | L11: ='IDA BRT'!H82 -> 26.575417 | M11: ='IDA BRT'!C83 -> 96.517812 | N11: ='IDA BRT'!D83 -> 6.4526042 | R11: PRINCIPAL | S11: San Juanito | T11: ='IDA BRT TRANS'!B83 -> 26.705 | U11: ='IDA BRT TRANS'!C83 -> 97.065104 | V11: ='IDA BRT TRANS'!D83 -> 6.5675 | Y11: =T11-(T11*0.03) -> 25.90385 | Z11: =U11-(U11*0.03) -> 94.153151 | AA11: =V11+(V11*0.03) -> 6.764525 | AC11: PRINCIPAL | AD11: San Juanito | AE11: 26.486979 | AF11: 90.347812 | AG11: 6.5071875 | AJ11: =T11-(T11*0.08) -> 24.5686 | AK11: =U11-(U11*0.08) -> 89.299896 | AL11: =V11+(V11*0.08) -> 7.0929 | AN11: PRINCIPAL | AO11: San Juanito | AP11: 24.496042 | AQ11: 82.527396 | AR11: 6.7210417 | AU11: =T11-(T11*0.14) -> 22.9663 | AV11: =U11-(U11*0.14) -> 83.47599 | AW11: =V11+(V11*0.14) -> 7.48695 | AY11: PRINCIPAL | AZ11: San Juanito | BA11: 23.968333 | BB11: 75.654062 | BC11: 6.7414583 | BF11: =T11-(T11*0.2) -> 21.364 | BG11: =U11-(U11*0.2) -> 77.652083 | BH11: =V11+(V11*0.2) -> 7.881 | BJ11: PRINCIPAL | BK11: San Juanito | BL11: 23.73625 | BM11: 69.374271 | BN11: 6.835
B12: LATERAL | D12: ='IDA ORIGINAL'!B114 -> 24.1375 | E12: ='IDA ORIGINAL'!C114 -> 88.775104 | F12: ='IDA ORIGINAL'!D114 -> 6.3969792 | J12: LATERAL | L12: ='IDA BRT'!B111 -> 21.234167 | M12: ='IDA BRT'!C111 -> 67.794792 | N12: ='IDA BRT'!D111 -> 6.818125 | R12: LATERAL | T12: ='IDA BRT TRANS'!B111 -> 21.031875 | U12: ='IDA BRT TRANS'!C111 -> 67.517813 | V12: ='IDA BRT TRANS'!D111 -> 6.8123958 | Y12: =T12-(T12*0.03) -> 20.400919 | Z12: =U12-(U12*0.03) -> 65.492278 | AA12: =V12+(V12*0.03) -> 7.0167677 | AC12: LATERAL | AE12: 20.920833 | AF12: 68.210729 | AG12: 6.7777083 | AJ12: =T12-(T12*0.08) -> 19.349325 | AK12: =U12-(U12*0.08) -> 62.116388 | AL12: =V12+(V12*0.08) -> 7.3573875 | AN12: LATERAL | AP12: 20.361771 | AQ12: 60.537292 | AR12: 6.8207292 | AU12: =T12-(T12*0.14) -> 18.087412 | AV12: =U12-(U12*0.14) -> 58.065319 | AW12: =V12+(V12*0.14) -> 7.7661313 | AY12: LATERAL | BA12: 20.241563 | BB12: 55.555208 | BC12: 6.9302083 | BF12: =T12-(T12*0.2) -> 16.8255 | BG12: =U12-(U12*0.2) -> 54.01425 | BH12: =V12+(V12*0.2) -> 8.174875 | BJ12: LATERAL | BL12: 19.345312 | BM12: 52.668437 | BN12: 6.9382292
B13: PRINCIPAL | C13: Av. Escuadron | D13: ='IDA ORIGINAL'!B146 -> 25.092292 | E13: ='IDA ORIGINAL'!C146 -> 101.35052 | F13: ='IDA ORIGINAL'!D146 -> 6.9079167 | J13: PRINCIPAL | K13: Av. Escuadron | L13: ='IDA BRT'!B143 -> 21.85125 | M13: ='IDA BRT'!C143 -> 90.562396 | N13: ='IDA BRT'!D143 -> 7.18625 | R13: PRINCIPAL | S13: Av. Escuadron | T13: ='IDA BRT TRANS'!B143 -> 22.209583 | U13: ='IDA BRT TRANS'!C143 -> 91.099792 | V13: ='IDA BRT TRANS'!D143 -> 7.1373958 | Y13: =T13-(T13*0.03) -> 21.543296 | Z13: =U13-(U13*0.03) -> 88.366798 | AA13: =V13+(V13*0.03) -> 7.3515177 | AC13: PRINCIPAL | AD13: Av. Escuadron | AE13: 21.041146 | AF13: 82.441771 | AG13: 7.4484375 | AJ13: =T13-(T13*0.08) -> 20.432817 | AK13: =U13-(U13*0.08) -> 83.811808 | AL13: =V13+(V13*0.08) -> 7.7083875 | AN13: PRINCIPAL | AO13: Av. Escuadron | AP13: 19.73625 | AQ13: 74.259271 | AR13: 7.6745833 | AU13: =T13-(T13*0.14) -> 19.100242 | AV13: =U13-(U13*0.14) -> 78.345821 | AW13: =V13+(V13*0.14) -> 8.1366313 | AY13: PRINCIPAL | AZ13: Av. Escuadron | BA13: 18.905104 | BB13: 68.1075 | BC13: 7.7219792 | BF13: =T13-(T13*0.2) -> 17.767667 | BG13: =U13-(U13*0.2) -> 72.879833 | BH13: =V13+(V13*0.2) -> 8.564875 | BJ13: PRINCIPAL | BK13: Av. Escuadron | BL13: 19.346354 | BM13: 64.296354 | BN13: 7.6452083
B14: LATERAL | D14: ='IDA ORIGINAL'!B174 -> 23.543437 | E14: ='IDA ORIGINAL'!C174 -> 130.81135 | F14: ='IDA ORIGINAL'!D174 -> 5.4454167 | J14: LATERAL | L14: ='IDA BRT'!B171 -> 23.040104 | M14: ='IDA BRT'!C171 -> 67.314167 | N14: ='IDA BRT'!D171 -> 6.4960417 | R14: LATERAL | T14: ='IDA BRT TRANS'!B171 -> 23.596979 | U14: ='IDA BRT TRANS'!C171 -> 69.753542 | V14: ='IDA BRT TRANS'!D171 -> 6.5045833 | Y14: =T14-(T14*0.03) -> 22.88907 | Z14: =U14-(U14*0.03) -> 67.660935 | AA14: =V14+(V14*0.03) -> 6.6997208 | AC14: LATERAL | AE14: 21.46375 | AF14: 62.099062 | AG14: 6.6211458 | AJ14: =T14-(T14*0.08) -> 21.709221 | AK14: =U14-(U14*0.08) -> 64.173258 | AL14: =V14+(V14*0.08) -> 7.02495 | AN14: LATERAL | AP14: 21.596979 | AQ14: 59.035 | AR14: 6.6990625 | AU14: =T14-(T14*0.14) -> 20.293402 | AV14: =U14-(U14*0.14) -> 59.988046 | AW14: =V14+(V14*0.14) -> 7.415225 | AY14: LATERAL | BA14: 22.547604 | BB14: 58.733958 | BC14: 6.6051042 | BF14: =T14-(T14*0.2) -> 18.877583 | BG14: =U14-(U14*0.2) -> 55.802833 | BH14: =V14+(V14*0.2) -> 7.8055 | BJ14: LATERAL | BL14: 21.321562 | BM14: 53.641354 | BN14: 6.8261458
C15: Monumento | D15: ='IDA ORIGINAL'!B218 -> 100.79944 | E15: ='IDA ORIGINAL'!C218 -> 223.33132 | F15: ='IDA ORIGINAL'!D218 -> 1.4290278 | K15: Monumento | L15: ='IDA BRT'!B215 -> 35.041736 | M15: ='IDA BRT'!C215 -> 110.48868 | N15: ='IDA BRT'!D215 -> 3.820625 | S15: Monumento | T15: ='IDA BRT TRANS'!B215 -> 40.572917 | U15: ='IDA BRT TRANS'!C215 -> 126.15361 | V15: ='IDA BRT TRANS'!D215 -> 3.2095833 | Y15: =T15-(T15*0.03) -> 39.355729 | Z15: =U15-(U15*0.03) -> 122.369 | AA15: =V15+(V15*0.03) -> 3.3058708 | AD15: Monumento | AE15: 33.660625 | AF15: 105.90701 | AG15: 3.9786806 | AJ15: =T15-(T15*0.08) -> 37.327083 | AK15: =U15-(U15*0.08) -> 116.06132 | AL15: =V15+(V15*0.08) -> 3.46635 | AO15: Monumento | AP15: 33.243889 | AQ15: 102.55507 | AR15: 3.9955556 | AU15: =T15-(T15*0.14) -> 34.892708 | AV15: =U15-(U15*0.14) -> 108.49211 | AW15: =V15+(V15*0.14) -> 3.658925 | AZ15: Monumento | BA15: 32.306181 | BB15: 95.140694 | BC15: 4.0686111 | BF15: =T15-(T15*0.2) -> 32.458333 | BG15: =U15-(U15*0.2) -> 100.92289 | BH15: =V15+(V15*0.2) -> 3.8515 | BK15: Monumento | BL15: 32.212778 | BM15: 89.028333 | BN15: 4.1597222
C16: Michelena | D16: 36.3575 | E16: 80.237917 | F16: 1.6670833 | K16: Michelena | L16: 23.374167 | M16: 66.409583 | N16: 2.5783333 | S16: Michelena | T16: 26.945544 | U16: 72.239167 | V16: 2.0655444 | Y16: =T16-(T16*0.03) -> 26.137178 | Z16: =U16-(U16*0.03) -> 70.071992 | AA16: =V16+(V16*0.03) -> 2.1275108 | AD16: Michelena | AE16: 24.402083 | AF16: 64.809167 | AG16: 2.520625 | AJ16: =T16-(T16*0.08) -> 24.789901 | AK16: =U16-(U16*0.08) -> 66.460033 | AL16: =V16+(V16*0.08) -> 2.230788 | AO16: Michelena | AP16: 23.686354 | AQ16: 63.194167 | AR16: 2.5672917 | AU16: =T16-(T16*0.14) -> 23.173168 | AV16: =U16-(U16*0.14) -> 62.125683 | AW16: =V16+(V16*0.14) -> 2.3547207 | AZ16: Michelena | BA16: 24.324583 | BB16: 61.143229 | BC16: 2.5453125 | BF16: =T16-(T16*0.2) -> 21.556435 | BG16: =U16-(U16*0.2) -> 57.791333 | BH16: =V16+(V16*0.2) -> 2.4786533 | BK16: Michelena | BL16: 22.987083 | BM16: 55.84375 | BN16: 2.66
C17: Pozarica | D17: ='IDA ORIGINAL'!B250 -> 42.478646 | E17: ='IDA ORIGINAL'!C250 -> 91.871563 | F17: ='IDA ORIGINAL'!D250 -> 2.320625 | K17: Pozarica | L17: ='IDA BRT'!B247 -> 40.720937 | M17: ='IDA BRT'!C247 -> 83.375833 | N17: ='IDA BRT'!D247 -> 3.1216667 | S17: Pozarica | T17: ='IDA BRT TRANS'!B247 -> 43.988021 | U17: ='IDA BRT TRANS'!C247 -> 94.376042 | V17: ='IDA BRT TRANS'!D247 -> 2.4482292 | Y17: =T17-(T17*0.03) -> 42.66838 | Z17: =U17-(U17*0.03) -> 91.54476 | AA17: =V17+(V17*0.03) -> 2.521676 | AD17: Pozarica | AE17: 39.531458 | AF17: 87.222292 | AG17: 2.5290625 | AJ17: =T17-(T17*0.08) -> 40.468979 | AK17: =U17-(U17*0.08) -> 86.825958 | AL17: =V17+(V17*0.08) -> 2.6440875 | AO17: Pozarica | AP17: 38.684688 | AQ17: 79.814583 | AR17: 2.5439583 | AU17: =T17-(T17*0.14) -> 37.829698 | AV17: =U17-(U17*0.14) -> 81.163396 | AW17: =V17+(V17*0.14) -> 2.7909813 | AZ17: Pozarica | BA17: 37.013021 | BB17: 74.040833 | BC17: 2.6905208 | BF17: =T17-(T17*0.2) -> 35.190417 | BG17: =U17-(U17*0.2) -> 75.500833 | BH17: =V17+(V17*0.2) -> 2.937875 | BK17: Pozarica | BL17: 36.899792 | BM17: 73.586979 | BN17: 2.685625
C18: Caballito | D18: 20.015833 | E18: 64.899167 | F18: 6.97 | K18: Caballito | L18: 13.330833 | M18: 54.188333 | N18: 7.7616667 | S18: Caballito | T18: 13.435556 | U18: 53.416667 | V18: 7.6958333 | Y18: =T18-(T18*0.03) -> 13.032489 | Z18: =U18-(U18*0.03) -> 51.814167 | AA18: =V18+(V18*0.03) -> 7.9267083 | AD18: Caballito | AE18: 11.570208 | AF18: 48.65625 | AG18: 8.3938542 | AJ18: =T18-(T18*0.08) -> 12.360711 | AK18: =U18-(U18*0.08) -> 49.143333 | AL18: =V18+(V18*0.08) -> 8.3115 | AO18: Caballito | AP18: 9.0161458 | AQ18: 41.963437 | AR18: 9.0716667 | AU18: =T18-(T18*0.14) -> 11.554578 | AV18: =U18-(U18*0.14) -> 45.938333 | AW18: =V18+(V18*0.14) -> 8.77325 | AZ18: Caballito | BA18: 6.2585417 | BB18: 32.069063 | BC18: 10.184062 | BF18: =T18-(T18*0.2) -> 10.748444 | BG18: =U18-(U18*0.2) -> 42.733333 | BH18: =V18+(V18*0.2) -> 9.235 | BK18: Caballito | BL18: 6.7370833 | BM18: 31.925417 | BN18: 10.085417
B19: PRINCIPAL | C19: Salida Charo | D19: ='IDA ORIGINAL'!B282 -> 14.291771 | E19: ='IDA ORIGINAL'!C282 -> 67.885729 | F19: ='IDA ORIGINAL'!D282 -> 6.3892708 | J19: PRINCIPAL | K19: Salida Charo | L19: ='IDA BRT'!B279 -> 13.726146 | M19: ='IDA BRT'!C279 -> 65.273125 | N19: ='IDA BRT'!D279 -> 6.656875 | R19: PRINCIPAL | S19: Salida Charo | T19: ='IDA BRT TRANS'!B279 -> 14.274271 | U19: ='IDA BRT TRANS'!C279 -> 66.946771 | V19: ='IDA BRT TRANS'!D279 -> 6.5854167 | Y19: =T19-(T19*0.03) -> 13.846043 | Z19: =U19-(U19*0.03) -> 64.938368 | AA19: =V19+(V19*0.03) -> 6.7829792 | AC19: PRINCIPAL | AD19: Salida Charo | AE19: 14.182708 | AF19: 61.078333 | AG19: 6.84125 | AJ19: =T19-(T19*0.08) -> 13.132329 | AK19: =U19-(U19*0.08) -> 61.591029 | AL19: =V19+(V19*0.08) -> 7.11225 | AN19: PRINCIPAL | AO19: Salida Charo | AP19: 14.785833 | AQ19: 61.117396 | AR19: 6.6766667 | AU19: =T19-(T19*0.14) -> 12.275873 | AV19: =U19-(U19*0.14) -> 57.574223 | AW19: =V19+(V19*0.14) -> 7.507375 | AY19: PRINCIPAL | AZ19: Salida Charo | BA19: 14.693125 | BB19: 59.056146 | BC19: 6.7215625 | BF19: =T19-(T19*0.2) -> 11.419417 | BG19: =U19-(U19*0.2) -> 53.557417 | BH19: =V19+(V19*0.2) -> 7.9025 | BJ19: PRINCIPAL | BK19: Salida Charo | BL19: 14.617604 | BM19: 58.333646 | BN19: 6.7535417
B20: LATERAL | D20: ='IDA ORIGINAL'!B310 -> 15.474479 | E20: ='IDA ORIGINAL'!C310 -> 57.23125 | F20: ='IDA ORIGINAL'!D310 -> 4.9884375 | J20: LATERAL | L20: ='IDA BRT'!B307 -> 15.353854 | M20: ='IDA BRT'!C307 -> 55.444479 | N20: ='IDA BRT'!D307 -> 5.4783333 | R20: LATERAL | T20: ='IDA BRT TRANS'!B307 -> 16.914062 | U20: ='IDA BRT TRANS'!C307 -> 75.315417 | V20: ='IDA BRT TRANS'!D307 -> 5.1552083 | Y20: =T20-(T20*0.03) -> 16.406641 | Z20: =U20-(U20*0.03) -> 73.055954 | AA20: =V20+(V20*0.03) -> 5.3098646 | AC20: LATERAL | AE20: 16.209687 | AF20: 68.467604 | AG20: 5.2796875 | AJ20: =T20-(T20*0.08) -> 15.560937 | AK20: =U20-(U20*0.08) -> 69.290183 | AL20: =V20+(V20*0.08) -> 5.567625 | AN20: LATERAL | AP20: 16.301354 | AQ20: 67.597083 | AR20: 5.2979167 | AU20: =T20-(T20*0.14) -> 14.546094 | AV20: =U20-(U20*0.14) -> 64.771258 | AW20: =V20+(V20*0.14) -> 5.8769375 | AY20: LATERAL | BA20: 16.175937 | BB20: 71.056042 | BC20: 5.2458333 | BF20: =T20-(T20*0.2) -> 13.53125 | BG20: =U20-(U20*0.2) -> 60.252333 | BH20: =V20+(V20*0.2) -> 6.18625 | BJ20: LATERAL | BL20: 16.491458 | BM20: 68.708229 | BN20: 5.2210417
B23: Detectores VUELTA | J23: Detectores VUELTA | R23: Detectores VUELTA | AC23: Detectores VUELTA | AN23: Detectores VUELTA | AY23: Detectores VUELTA | BJ23: Detectores VUELTA
C26: Intersecciones | D26: TIEMPO ESPERA | E26: LONG COLA | F26: VELOCIDAD | G26: TIEMPO VIAJE | K26: Intersecciones | L26: TIEMPO ESPERA | M26: LONG COLA | N26: VELOCIDAD | O26: TIEMPO VIAJE | S26: Intersecciones | T26: TIEMPO ESPERA | U26: LONG COLA | V26: VELOCIDAD | W26: TIEMPO VIAJE | AD26: Intersecciones | AE26: TIEMPO ESPERA | AF26: LONG COLA | AG26: VELOCIDAD | AH26: TIEMPO VIAJE | AO26: Intersecciones | AP26: TIEMPO ESPERA | AQ26: LONG COLA | AR26: VELOCIDAD | AS26: TIEMPO VIAJE | AZ26: Intersecciones | BA26: TIEMPO ESPERA | BB26: LONG COLA | BC26: VELOCIDAD | BD26: TIEMPO VIAJE | BK26: Intersecciones | BL26: TIEMPO ESPERA | BM26: LONG COLA | BN26: VELOCIDAD | BO26: TIEMPO VIAJE
C27: Salida Quiroga | D27: ='VUELTA ORIGINAL'!B51 -> 42.98375 | E27: ='VUELTA ORIGINAL'!C51 -> 136.82313 | F27: ='VUELTA ORIGINAL'!D51 -> 3.7099306 | K27: Salida Quiroga | L27: ='VUELTA BRT'!B51 -> 17.593264 | M27: ='VUELTA BRT'!C51 -> 98.302222 | N27: ='VUELTA BRT'!D51 -> 7.2677083 | S27: Salida Quiroga | T27: ='VUELTA BRT TRANS'!B51 -> 17.361736 | U27: ='VUELTA BRT TRANS'!C51 -> 99.133194 | V27: ='VUELTA BRT TRANS'!D51 -> 7.3414583 | Y27: =T27-(T27*0.03) -> 16.840884 | Z27: =U27-(U27*0.03) -> 96.159199 | AA27: =V27-(V27*0.03) -> 7.1212146 | AD27: Salida Quiroga | AE27: 16.327708 | AF27: 102.03948 | AG27: 7.5342708 | AJ27: =T27-(T27*0.08) -> 15.972797 | AK27: =U27-(U27*0.08) -> 91.202539 | AL27: =V27+(V27*0.08) -> 7.928775 | AO27: Salida Quiroga | AP27: 15.921354 | AQ27: 92.95 | AR27: 7.6328125 | AU27: =T27-(T27*0.14) -> 14.931093 | AV27: =U27-(U27*0.14) -> 85.254547 | AW27: =V27+(V27*0.14) -> 8.3692625 | AZ27: Salida Quiroga | BA27: 15.245104 | BB27: 85.661354 | BC27: 7.8939583 | BF27: =T27-(T27*0.2) -> 13.889389 | BG27: =U27-(U27*0.2) -> 79.306556 | BH27: =V27+(V27*0.2) -> 8.80975 | BK27: Salida Quiroga | BL27: 14.124896 | BM27: 83.744583 | BN27: 8.3163542 | BO27: 2250.33
B28: PRINCIPAL | C28: San Juanito | D28: ='VUELTA ORIGINAL'!B83 -> 21.654687 | E28: ='VUELTA ORIGINAL'!C83 -> 100.41833 | F28: ='VUELTA ORIGINAL'!D83 -> 6.5380208 | J28: PRINCIPAL | K28: San Juanito | L28: ='VUELTA BRT'!B83 -> 18.634062 | M28: ='VUELTA BRT'!C83 -> 98.873333 | N28: ='VUELTA BRT'!D83 -> 7.9078125 | R28: PRINCIPAL | S28: San Juanito | T28: ='VUELTA BRT TRANS'!B83 -> 19.499792 | U28: ='VUELTA BRT TRANS'!C83 -> 100.54031 | V28: ='VUELTA BRT TRANS'!D83 -> 6.9005208 | Y28: =T28-(T28*0.03) -> 18.914798 | Z28: =U28-(U28*0.03) -> 97.524103 | AA28: =V28-(V28*0.03) -> 6.6935052 | AC28: PRINCIPAL | AD28: San Juanito | AE28: 21.513646 | AF28: 95.525 | AG28: 6.5534375 | AJ28: =T28-(T28*0.08) -> 17.939808 | AK28: =U28-(U28*0.08) -> 92.497087 | AL28: =V28+(V28*0.08) -> 7.4525625 | AN28: PRINCIPAL | AO28: San Juanito | AP28: 20.535417 | AQ28: 89.278125 | AR28: 6.6665625 | AU28: =T28-(T28*0.14) -> 16.769821 | AV28: =U28-(U28*0.14) -> 86.464669 | AW28: =V28+(V28*0.14) -> 7.8665938 | AY28: PRINCIPAL | AZ28: San Juanito | BA28: 20.684792 | BB28: 85.084063 | BC28: 6.5751042 | BF28: =T28-(T28*0.2) -> 15.599833 | BG28: =U28-(U28*0.2) -> 80.43225 | BH28: =V28+(V28*0.2) -> 8.280625 | BJ28: PRINCIPAL | BK28: San Juanito | BL28: 20.458333 | BM28: 76.780833 | BN28: 6.6888542
B29: LATERAL | D29: ='VUELTA ORIGINAL'!B111 -> 24.619063 | E29: ='VUELTA ORIGINAL'!C111 -> 51.720312 | F29: ='VUELTA ORIGINAL'!D111 -> 6.4309375 | J29: LATERAL | L29: ='VUELTA BRT'!B111 -> 22.355729 | M29: ='VUELTA BRT'!C111 -> 48.239271 | N29: ='VUELTA BRT'!D111 -> 7.05875 | R29: LATERAL | T29: ='VUELTA BRT TRANS'!B111 -> 22.144167 | U29: ='VUELTA BRT TRANS'!C111 -> 48.691458 | V29: ='VUELTA BRT TRANS'!D111 -> 7.31375 | Y29: =T29-(T29*0.03) -> 21.479842 | Z29: =U29-(U29*0.03) -> 47.230715 | AA29: =V29-(V29*0.03) -> 7.0943375 | AC29: LATERAL | AE29: 22.326771 | AF29: 49.747083 | AG29: 6.8763542 | AJ29: =T29-(T29*0.08) -> 20.372633 | AK29: =U29-(U29*0.08) -> 44.796142 | AL29: =V29+(V29*0.08) -> 7.89885 | AN29: LATERAL | AP29: 21.862813 | AQ29: 46.919688 | AR29: 6.9291667 | AU29: =T29-(T29*0.14) -> 19.043983 | AV29: =U29-(U29*0.14) -> 41.874654 | AW29: =V29+(V29*0.14) -> 8.337675 | AY29: LATERAL | BA29: 21.112708 | BB29: 45.280729 | BC29: 7.0858333 | BF29: =T29-(T29*0.2) -> 17.715333 | BG29: =U29-(U29*0.2) -> 38.953167 | BH29: =V29+(V29*0.2) -> 8.7765 | BJ29: LATERAL | BL29: 23.023021 | BM29: 45.078333 | BN29: 6.9014583
B30: PRINCIPAL | C30: Av. Escuadron | D30: ='VUELTA ORIGINAL'!B143 -> 20.804167 | E30: ='VUELTA ORIGINAL'!C143 -> 35.153021 | F30: ='VUELTA ORIGINAL'!D143 -> 7.281875 | J30: PRINCIPAL | K30: Av. Escuadron | L30: ='VUELTA BRT'!B143 -> 20.544479 | M30: ='VUELTA BRT'!C143 -> 35.130104 | N30: ='VUELTA BRT'!D143 -> 7.3109375 | R30: PRINCIPAL | S30: Av. Escuadron | T30: ='VUELTA BRT TRANS'!B143 -> 21.393437 | U30: ='VUELTA BRT TRANS'!C143 -> 35.724062 | V30: ='VUELTA BRT TRANS'!D143 -> 7.1269792 | Y30: =T30-(T30*0.03) -> 20.751634 | Z30: =U30-(U30*0.03) -> 34.652341 | AA30: =V30-(V30*0.03) -> 6.9131698 | AC30: PRINCIPAL | AD30: Av. Escuadron | AE30: 19.684167 | AF30: 33.725833 | AG30: 7.2995833 | AJ30: =T30-(T30*0.08) -> 19.681962 | AK30: =U30-(U30*0.08) -> 32.866137 | AL30: =V30+(V30*0.08) -> 7.6971375 | AN30: PRINCIPAL | AO30: Av. Escuadron | AP30: 18.817708 | AQ30: 30.130833 | AR30: 7.42375 | AU30: =T30-(T30*0.14) -> 18.398356 | AV30: =U30-(U30*0.14) -> 30.722694 | AW30: =V30+(V30*0.14) -> 8.1247563 | AY30: PRINCIPAL | AZ30: Av. Escuadron | BA30: 19.126771 | BB30: 28.581563 | BC30: 7.4135417 | BF30: =T30-(T30*0.2) -> 17.11475 | BG30: =U30-(U30*0.2) -> 28.57925 | BH30: =V30+(V30*0.2) -> 8.552375 | BJ30: PRINCIPAL | BK30: Av. Escuadron | BL30: 19.258854 | BM30: 26.975729 | BN30: 7.2629167
B31: LATERAL | D31: ='VUELTA ORIGINAL'!B171 -> 10.341979 | E31: ='VUELTA ORIGINAL'!C171 -> 40.21125 | F31: ='VUELTA ORIGINAL'!D171 -> 10.999375 | J31: LATERAL | L31: 8.25375 | M31: 27.638333 | N31: 12.15 | R31: LATERAL | T31: 9.7544333 | U31: 29.457667 | V31: 11.011111 | Y31: =T31-(T31*0.03) -> 9.4618003 | Z31: =U31-(U31*0.03) -> 28.573937 | AA31: =V31-(V31*0.03) -> 10.680778 | AC31: LATERAL | AE31: 6.5514583 | AF31: 23.242292 | AG31: 9.8726042 | AJ31: =T31-(T31*0.08) -> 8.9740787 | AK31: =U31-(U31*0.08) -> 27.101053 | AL31: =V31+(V31*0.08) -> 11.892 | AN31: LATERAL | AP31: 7.3467708 | AQ31: 22.97 | AR31: 9.5255208 | AU31: =T31-(T31*0.14) -> 8.3888127 | AV31: =U31-(U31*0.14) -> 25.333593 | AW31: =V31+(V31*0.14) -> 12.552667 | AY31: LATERAL | BA31: 6.7815625 | BB31: 20.206979 | BC31: 9.8776042 | BF31: =T31-(T31*0.2) -> 7.8035467 | BG31: =U31-(U31*0.2) -> 23.566133 | BH31: =V31+(V31*0.2) -> 13.213333 | BJ31: LATERAL | BL31: 6.4304167 | BM31: 20.34 | BN31: 9.9741667
C32: Monumento | D32: ='VUELTA ORIGINAL'!B215 -> 43.229583 | E32: ='VUELTA ORIGINAL'!C215 -> 159.89687 | F32: ='VUELTA ORIGINAL'!D215 -> 1.9968056 | K32: Monumento | L32: ='VUELTA BRT'!B187 -> 33.20375 | M32: ='VUELTA BRT'!C187 -> 109.93215 | N32: ='VUELTA BRT'!D187 -> 3.0236111 | S32: Monumento | T32: ='VUELTA BRT TRANS'!B187 -> 37.079514 | U32: ='VUELTA BRT TRANS'!C187 -> 126.61785 | V32: ='VUELTA BRT TRANS'!D187 -> 2.6439583 | Y32: =T32-(T32*0.03) -> 35.967128 | Z32: =U32-(U32*0.03) -> 122.81931 | AA32: =V32-(V32*0.03) -> 2.5646396 | AD32: Monumento | AE32: 33.374792 | AF32: 110.68111 | AG32: 2.8636806 | AJ32: =T32-(T32*0.08) -> 34.113153 | AK32: =U32-(U32*0.08) -> 116.48842 | AL32: =V32+(V32*0.08) -> 2.855475 | AO32: Monumento | AP32: 31.707431 | AQ32: 104.26354 | AR32: 3.0577778 | AU32: =T32-(T32*0.14) -> 31.888382 | AV32: =U32-(U32*0.14) -> 108.89135 | AW32: =V32+(V32*0.14) -> 3.0141125 | AZ32: Monumento | BA32: 31.205208 | BB32: 98.469375 | BC32: 3.0928472 | BF32: =T32-(T32*0.2) -> 29.663611 | BG32: =U32-(U32*0.2) -> 101.29428 | BH32: =V32+(V32*0.2) -> 3.17275 | BK32: Monumento | BL32: 30.676944 | BM32: 92.279167 | BN32: 3.1363889
C33: Pozarica | D33: ='VUELTA ORIGINAL'!B247 -> 12.255521 | E33: 106.78156 | F33: ='VUELTA ORIGINAL'!D247 -> 7.1265625 | K33: Pozarica | L33: ='VUELTA BRT'!B219 -> 8.0503125 | M33: ='VUELTA BRT'!C219 -> 55.055833 | N33: ='VUELTA BRT'!D219 -> 8.7478125 | S33: Pozarica | T33: ='VUELTA BRT TRANS'!B219 -> 10.011458 | U33: ='VUELTA BRT TRANS'!C219 -> 58.25625 | V33: ='VUELTA BRT TRANS'!D219 -> 8.190625 | Y33: =T33-(T33*0.03) -> 9.7111146 | Z33: =U33-(U33*0.03) -> 56.508563 | AA33: =V33-(V33*0.03) -> 7.9449062 | AD33: Pozarica | AE33: 7.25875 | AF33: 51.853333 | AG33: 9.1238542 | AJ33: =T33-(T33*0.08) -> 9.2105417 | AK33: =U33-(U33*0.08) -> 53.59575 | AL33: =V33+(V33*0.08) -> 8.845875 | AO33: Pozarica | AP33: 6.3347917 | AQ33: 42.313333 | AR33: 9.4694792 | AU33: =T33-(T33*0.14) -> 8.6098542 | AV33: =U33-(U33*0.14) -> 50.100375 | AW33: =V33+(V33*0.14) -> 9.3373125 | AZ33: Pozarica | BA33: 5.3891667 | BB33: 41.935 | BC33: 10.118333 | BF33: =T33-(T33*0.2) -> 8.0091667 | BG33: =U33-(U33*0.2) -> 46.605 | BH33: =V33+(V33*0.2) -> 9.82875 | BK33: Pozarica | BL33: 4.629375 | BM33: 33.949479 | BN33: 10.576771
B34: PRINCIPAL | C34: Salida Charo | D34: ='VUELTA ORIGINAL'!B279 -> 18.266875 | E34: ='VUELTA ORIGINAL'!C279 -> 96.500625 | F34: ='VUELTA ORIGINAL'!D279 -> 7.0053125 | J34: PRINCIPAL | K34: Salida Charo | L34: ='VUELTA BRT'!B251 -> 15.374896 | M34: ='VUELTA BRT'!C251 -> 40.187813 | N34: ='VUELTA BRT'!D251 -> 7.8433333 | R34: PRINCIPAL | S34: Salida Charo | T34: ='VUELTA BRT TRANS'!B251 -> 18.106667 | U34: ='VUELTA BRT TRANS'!C251 -> 43.885937 | V34: ='VUELTA BRT TRANS'!D251 -> 7.6276042 | Y34: =T34-(T34*0.03) -> 17.563467 | Z34: =U34-(U34*0.03) -> 42.569359 | AA34: =V34-(V34*0.03) -> 7.398776 | AC34: PRINCIPAL | AD34: Salida Charo | AE34: 12.934688 | AF34: 35.989792 | AG34: 9.3109375 | AJ34: =T34-(T34*0.08) -> 16.658133 | AK34: =U34-(U34*0.08) -> 40.375062 | AL34: =V34+(V34*0.08) -> 8.2378125 | AN34: PRINCIPAL | AO34: Salida Charo | AP34: 13.03 | AQ34: 35.520417 | AR34: 9.1738542 | AU34: =T34-(T34*0.14) -> 15.571733 | AV34: =U34-(U34*0.14) -> 37.741906 | AW34: =V34+(V34*0.14) -> 8.6954687 | AY34: PRINCIPAL | AZ34: Salida Charo | BA34: 12.654375 | BB34: 31.604792 | BC34: 9.29375 | BF34: =T34-(T34*0.2) -> 14.485333 | BG34: =U34-(U34*0.2) -> 35.10875 | BH34: =V34+(V34*0.2) -> 9.153125 | BJ34: PRINCIPAL | BK34: Salida Charo | BL34: 12.293437 | BM34: 29.775312 | BN34: 9.3815625
B35: LATERAL | D35: ='VUELTA ORIGINAL'!B307 -> 19.97125 | E35: ='VUELTA ORIGINAL'!C307 -> 82.215833 | F35: ='VUELTA ORIGINAL'!D307 -> 6.9885417 | J35: LATERAL | L35: ='VUELTA BRT'!B279 -> 13.769271 | M35: ='VUELTA BRT'!C279 -> 38.755938 | N35: ='VUELTA BRT'!D279 -> 8.9792708 | R35: LATERAL | T35: ='VUELTA BRT TRANS'!B279 -> 18.520833 | U35: ='VUELTA BRT TRANS'!C279 -> 43.470938 | V35: ='VUELTA BRT TRANS'!D279 -> 6.8428125 | Y35: =T35-(T35*0.03) -> 17.965208 | Z35: =U35-(U35*0.03) -> 42.166809 | AA35: =V35-(V35*0.03) -> 6.6375281 | AC35: LATERAL | AE35: 17.771875 | AF35: 91.7425 | AG35: 7.0205208 | AJ35: =T35-(T35*0.08) -> 17.039167 | AK35: =U35-(U35*0.08) -> 39.993263 | AL35: =V35+(V35*0.08) -> 7.3902375 | AN35: LATERAL | AP35: 17.731667 | AQ35: 89.76 | AR35: 7.0125 | AU35: =T35-(T35*0.14) -> 15.927917 | AV35: =U35-(U35*0.14) -> 37.385006 | AW35: =V35+(V35*0.14) -> 7.8008062 | AY35: LATERAL | BA35: 17.555208 | BB35: 83.648438 | BC35: 7.0733333 | BF35: =T35-(T35*0.2) -> 14.816667 | BG35: =U35-(U35*0.2) -> 34.77675 | BH35: =V35+(V35*0.2) -> 8.211375 | BJ35: LATERAL | BL35: 16.755208 | BM35: 81.204792 | BN35: 7.1652083

Sheet IDA ORIGINAL
B2: Intersecciones IDA | I2: 2750
H4: Corridas | I4: Segundos | J4: Velocidad
G5: Tiempo de Viaje | H5: 1 | I5: 2325.0967 | J5: 11.652222
H6: 2 | I6: 2446 | J6: 9.94
H7: 3 | I7: 2437 | J7: 9.89
H8: 4 | I8: 4552
B9: Salida Quiroga
B11: Corrida 1 | E11: Corrida 2 | H11: Corrida 3 | K11: Corrida 4
B12: Tiempos de espera | C12: Long. Cola | D12: Velocidad | E12: Tiempos de espera | F12: Long. Cola | G12: Velocidad | H12: Tiempos de espera | I12: Long. Cola | J12: Velocidad | K12: Tiempos de espera | L12: Long. Cola | M12: Velocidad
B13: 9.26 | C13: 41.04 | D13: 8.85 | E13: 15.85 | F13: 73.51 | G13: 6.33 | H13: 13.79 | I13: 56.29 | J13: 6.77 | K13: 11.04 | L13: 48.52 | M13: 7.7
B14: 15.27 | C14: 56.16 | D14: 6.28 | E14: 12.41 | F14: 66.02 | G14: 6.52 | H14: 17.01 | I14: 71.22 | J14: 5.44 | K14: 13.38 | L14: 63.63 | M14: 6.83
B15: 13.41 | C15: 41.09 | D15: 6.85 | E15: 15.36 | F15: 48.54 | G15: 6.11 | H15: 14.07 | I15: 56.08 | J15: 6.64 | K15: 13.57 | L15: 56.09 | M15: 7.09
B16: 17.68 | C16: 78.69 | D16: 5.13 | E16: 21.42 | F16: 71.09 | G16: 5.13 | H16: 16.76 | I16: 59.12 | J16: 5.74 | K16: 18.76 | L16: 80.99 | M16: 5.09
B17: 14.81 | C17: 71.07 | D17: 6.36 | E17: 11.94 | F17: 56.15 | G17: 6.95 | H17: 14.04 | I17: 63.5 | J17: 6.52 | K17: 14 | L17: 56.06 | M17: 6.52
B18: 14.61 | C18: 48.73 | D18: 6.56 | E18: 13.94 | F18: 41.15 | G18: 6.72 | H18: 12.8 | I18: 48.88 | J18: 6.24 | K18: 14.8 | L18: 48.7 | M18: 6.34
B19: 21.24 | C19: 78.55 | D19: 4.79 | E19: 18.49 | F19: 71.14 | G19: 5.58 | H19: 19.24 | I19: 65.3 | J19: 5.7 | K19: 14.77 | L19: 57.02 | M19: 6.51
B20: 11.94 | C20: 41 | D20: 7.49 | E20: 17.79 | F20: 56 | G20: 5.48 | H20: 17.66 | I20: 71.19 | J20: 5.78 | K20: 13.56 | L20: 63.65 | M20: 6.59
B21: 10.17 | C21: 48.67 | D21: 7.6 | E21: 10.2 | F21: 48.49 | G21: 7.67 | H21: 9.93 | I21: 48.59 | J21: 7.78 | K21: 8.22 | L21: 63.32 | M21: 8.93
B22: 14.34 | C22: 51.06 | D22: 6.1 | E22: 21.78 | F22: 71.11 | G22: 4.97 | H22: 18.12 | I22: 88.41 | J22: 5.66 | K22: 17.52 | L22: 71.17 | M22: 5.73
B23: 20.19 | C23: 71.14 | D23: 5.7 | E23: 15.2 | F23: 48.65 | G23: 6.13 | H23: 15.83 | I23: 70.96 | J23: 6.07 | K23: 23.41 | L23: 93.56 | M23: 4.88
B24: 11.56 | C24: 41.31 | D24: 7.33 | E24: 11.88 | F24: 48.54 | G24: 7.34 | H24: 9.91 | I24: 41.2 | J24: 8.11 | K24: 8.08 | L24: 33.61 | M24: 8.92
... B48: 23.51 | C48: 96.57 | D48: 4.96 | E48: 25.96 | F48: 101.69 | G48: 4.53 | H48: 21.97 | I48: 94.38 | J48: 5.14 | K48: 21.06 | L48: 79.34 | M48: 5.31
A50: PROMEDIOS | B50: =AVERAGE(B13:B48) -> 16.462222 | C50: =AVERAGE(C13:C48) -> 66.316944 | D50: =AVERAGE(D13:D48) -> 6.2086111 | E50: =AVERAGE(E13:E48) -> 16.937222 | F50: =AVERAGE(F13:F48) -> 61.37 | G50: =AVERAGE(G13:G48) -> 6.1775 | H50: =AVERAGE(H13:H48) -> 15.484167 | I50: =AVERAGE(I13:I48) -> 66.646667 | ... M50: =AVERAGE(M13:M48) -> 6.3736111
A51: PROMEDIO 4 | B51: =AVERAGE(B50,E50,H50,K50) -> 16.374792 | C51: =AVERAGE(C50,F50,I50,L50) -> 65.101458 | D51: =AVERAGE(D50,G50,J50,M50) -> 6.2702083
A52: ERROR AD | B52: =B51*0.05 -> 0.81873958 | C52: =C51*0.05 -> 3.2550729 | D52: =D51*0.05 -> 0.31351042
A53: DESVIAC | B53: =_xlfn.STDEV.S(B50,E50,H50,K50) -> 0.62587336 | C53: =_xlfn.STDEV.S(C50,F50,I50,L50) -> 2.498749 | D53: =_xlfn.STDEV.S(D50,G50,J50,M50) -> 0.09250636
A54: Nm | B54: =((2.92)*(B53/B52))^2 -> 4.9824971 | C54: =((2.92)*(C53/C52))^2 -> 5.0244614 | D54: =((2.92)*(D53/D52))^2 -> 0.74234355
B56: San Juanito
B58: Corrida 1 | E58: Corrida 2 | H58: Corrida 3 | K58: Corrida 4
B59: Tiempos de espera | C59: Long. Cola | D59: Velocidad | E59: Tiempos de espera | F59: Long. Cola | G59: Velocidad | H59: Tiempos de espera | I59: Long. Cola | J59: Velocidad | K59: Tiempos de espera | L59: Long. Cola | M59: Velocidad
A60: principal | B60: 11.73 | C60: 87.61 | D60: 8.57 | E60: 8.16 | F60: 49.77 | G60: 8.41 | H60: 9.99 | I60: 80.09 | J60: 8.32 | K60: 9.92 | L60: 72.59 | M60: 8.11
B61: 32.43 | C61: 147.75 | D61: 6.01 | E61: 32.5 | F61: 147.79 | G61: 6.01 | H61: 31.89 | I61: 162.89 | J61: 6.04 | K61: 33.35 | L61: 148.18 | M61: 5.85
B62: 42.05 | C62: 147.57 | D62: 4.43 | E62: 40.38 | F62: 147.8 | G62: 4.54 | H62: 39.3 | I62: 148.18 | J62: 4.47 | K62: 36.61 | L62: 139.45 | M62: 4.74
B63: 44.02 | C63: 131.9 | D63: 4.87 | E63: 49.69 | F63: 131.81 | G63: 4.71 | H63: 56.07 | I63: 117.56 | J63: 4.53 | K63: 53.43 | L63: 132.11 | M63: 4.38
B64: 13.53 | C64: 64.72 | D64: 6.41 | E64: 12.28 | F64: 64.71 | G64: 8.57 | H64: 12.82 | I64: 64.62 | J64: 6.41 | K64: 11.43 | L64: 64.69 | M64: 6.41
B65: 9.47 | C65: 35.14 | D65: 8.45 | E65: 9.47 | F65: 35.14 | G65: 8.45 | H65: 9.47 | I65: 35.14 | J65: 8.45 | K65: 9.47 | L65: 35.14 | M65: 8.45
B66: 13.53 | C66: 64.72 | D66: 8.57 | E66: 4.76 | F66: 4.12 | G66: 6.41 | H66: 10.14 | I66: 19.41 | J66: 6.41 | K66: 9.74 | L66: 19.37 | M66: 6.41
B67: 9.47 | C67: 35.14 | D67: 8.45 | E67: 1.65 | F67: 11.83 | G67: 8.45 | H67: 8.18 | I67: 11.97 | J67: 8.45 | K67: 5.85 | L67: 34.58 | M67: 8.45
B68: 23.74 | C68: 95 | D68: 6.41 | E68: 24.03 | F68: 95.22 | G68: 8.54 | H68: 24.23 | I68: 102.57 | J68: 8.54 | K68: 24.62 | L68: 110.42 | M68: 6.41
B69: 34.87 | C69: 140.29 | D69: 6.58 | E69: 34.47 | F69: 132.81 | G69: 6.47 | H69: 31.81 | I69: 155.95 | J69: 6.64 | K69: 32.55 | L69: 140.44 | M69: 6.57
...

Sheet VUELTA ORIGINAL
B2: Intersecciones VUELTA
H4: Corridas | I4: Segundos | J4: Velocidad
G5: Tiempo de Viaje | H5: 1 | I5: 2418.115 | J5: 11.715
H6: 2 | I6: 2413 | J6: 10.35
H7: 3 | I7: 2384 | J7: 10.26
H8: 4 | I8: 5436
B9: Salida Quiroga
B11: Corrida 1 | E11: Corrida 2 | H11: Corrida 3 | K11: Corrida 4
B12: Tiempos de espera | C12: Long. Cola | D12: Velocidad | E12: Tiempos de espera | F12: Long. Cola | G12: Velocidad | H12: Tiempos de espera | I12: Long. Cola | J12: Velocidad | K12: Tiempos de espera | L12: Long. Cola | M12: Velocidad
B13: 21.27 | C13: 123.12 | D13: 6.04 | E13: 19.9 | F13: 116.85 | G13: 6.18 | H13: 19.8 | I13: 123.33 | J13: 6.06 | K13: 18.75 | L13: 93.18 | M13: 6.6
B14: 15.33 | C14: 78.7 | D14: 7.03 | E14: 19.99 | F14: 124.25 | G14: 5.88 | H14: 14.45 | I14: 63.98 | J14: 7.42 | K14: 15.19 | L14: 78.54 | M14: 7.27
B15: 20.12 | C15: 123.26 | D15: 5.33 | E15: 15.18 | F15: 71.46 | G15: 6.42 | H15: 22.73 | I15: 139.11 | J15: 4.93 | K15: 16.58 | L15: 93.72 | M15: 6.29
B16: 23.84 | C16: 169.34 | D16: 5.06 | E16: 24.57 | F16: 161.81 | G16: 4.89 | H16: 25.59 | I16: 176.8 | J16: 4.91 | K16: 22.43 | L16: 138.97 | M16: 5.24
B17: 19.89 | C17: 176.54 | D17: 5.86 | E17: 22.19 | F17: 176.64 | G17: 5.32 | H17: 22.92 | I17: 198.98 | J17: 5.09 | K17: 18.17 | L17: 161.72 | M17: 6.24
B18: 21.41 | C18: 153.24 | D18: 5.8 | E18: 23.03 | F18: 154.48 | G18: 5.53 | H18: 22.37 | I18: 153.7 | J18: 5.31 | K18: 20.01 | L18: 168.92 | M18: 6.18
B19: 23.03 | C19: 134.75 | D19: 5.4 | E19: 22.98 | F19: 138.84 | G19: 5.38 | H19: 21.36 | I19: 149.03 | J19: 5.53 | K19: 21.45 | L19: 141.67 | M19: 5.44
B20: 17.39 | C20: 146.15 | D20: 6.28 | E20: 21.05 | F20: 175.89 | G20: 5.61 | H20: 18.9 | I20: 153.45 | J20: 5.7 | K20: 21.78 | L20: 191.7 | M20: 5.36
B21: 16.34 | C21: 123.7 | D21: 6.13 | E21: 10.61 | F21: 116.13 | G21: 7.6 | H21: 15.06 | I21: 115.6 | J21: 5.93 | K21: 16.63 | L21: 161.54 | M21: 5.67
B22: 19.78 | C22: 73.43 | D22: 6.3 | E22: 18.18 | F22: 81.26 | G22: 6.56 | H22: 21.28 | I22: 81.99 | J22: 5.8 | K22: 18.97 | L22: 71.12 | M22: 6.46
B23: 31.52 | C23: 199.92 | D23: 4.53 | E23: 29.92 | F23: 199.42 | G23: 4.66 | H23: 29.52 | I23: 199.61 | J23: 4.63 | K23: 27.87 | L23: 183.6 | M23: 4.77
B24: 25.77 | C24: 161.83 | D24: 4.61 | E24: 22.52 | F24: 161.46 | G24: 5 | H24: 18.74 | I24: 169.35 | J24: 5.64 | K24: 19.9 | L24: 161.59 | M24: 5.49
... B48: 123.93 | C48: 200 | D48: 0.79 | E48: 110.35 | F48: 200 | G48: 0.97 | H48: 110.04 | I48: 200 | J48: 0.95 | K48: 100.4 | L48: 200 | M48: 1
A50: PROMEDIO | B50: =AVERAGE(B13:B48) -> 42.261944 | C50: =AVERAGE(C13:C48) -> 134.73139 | D50: =AVERAGE(D13:D48) -> 3.7638889 | E50: =AVERAGE(E13:E48) -> 46.173889 | F50: =AVERAGE(F13:F48) -> 142.65056 | G50: =AVERAGE(G13:G48) -> 3.6208333 | H50: =AVERAGE(H13:H48) -> 43.069444 | I50: =AVERAGE(I13:I48) -> 138.00333 | ... M50: =AVERAGE(M13:M48) -> 3.84
A51: PROMEDIO 4 | B51: =AVERAGE(B50,E50,H50,K50) -> 42.98375 | C51: =AVERAGE(C50,F50,I50,L50) -> 136.82313 | D51: =AVERAGE(D50,G50,J50,M50) -> 3.7099306
B53: San Juanito
B55: Corrida 1 | E55: Corrida 2 | H55: Corrida 3 | K55: Corrida 4
B56: Tiempos de espera | C56: Long. Cola | D56: Velocidad | E56: Tiempos de espera | F56: Long. Cola | G56: Velocidad | H56: Tiempos de espera | I56: Long. Cola | J56: Velocidad | K56: Tiempos de espera | L56: Long. Cola | M56: Velocidad
A57: principal | B57: 22.56 | C57: 87.47 | D57: 5.49 | E57: 21.72 | F57: 73.53 | G57: 5.63 | H57: 24.32 | I57: 94.85 | J57: 5.56 | K57: 21.77 | L57: 94.9 | M57: 5.56
B58: 22.08 | C58: 87.4 | D58: 6.07 | E58: 19.67 | F58: 80.09 | G58: 5.99 | H58: 18.68 | I58: 72.55 | J58: 6.22 | K58: 20.1 | L58: 87.47 | M58: 5.64
B59: 21.9 | C59: 87.82 | D59: 6.23 | E59: 18.24 | F59: 72.51 | G59: 6.75 | H59: 22.81 | I59: 87.51 | J59: 6.08 | K59: 22.58 | L59: 109.98 | M59: 6.37
B60: 34.52 | C60: 140.04 | D60: 4.54 | E60: 33.64 | F60: 117.38 | G60: 4.21 | H60: 33.32 | I60: 132.42 | J60: 4.45 | K60: 30.87 | L60: 125 | M60: 4.51
B61: 22.41 | C61: 72.47 | D61: 5.08 | E61: 21.91 | F61: 79.97 | G61: 6.06 | H61: 23.58 | I61: 79.91 | J61: 4.97 | K61: 22.54 | L61: 81.09 | M61: 5.51
B62: 30.48 | C62: 124.83 | D62: 5.15 | E62: 33.47 | F62: 132.48 | G62: 4.76 | H62: 37.07 | I62: 132.35 | J62: 4.68 | K62: 33.79 | L62: 124.91 | M62: 4.71
B63: 21.04 | C63: 79.93 | D63: 5.54 | E63: 18.37 | F63: 79.89 | G63: 6.34 | H63: 25.5 | I63: 87.46 | J63: 5.06 | K63: 23.72 | L63: 73.52 | M63: 5.75
B64: 23.54 | C64: 87.36 | D64: 5.65 | E64: 33.33 | F64: 117.79 | G64: 5.03 | H64: 28.32 | I64: 96.19 | J64: 5.29 | K64: 28.38 | L64: 96.31 | M64: 5.54
B65: 41.41 | C65: 124.89 | D65: 3.88 | E65: 44.06 | F65: 118.55 | G65: 4.18 | H65: 37.07 | I65: 124.93 | J65: 4.31 | K65: 43.04 | L65: 124.96 | M65: 4.26
B66: 27.84 | C66: 117.49 | D66: 5.3 | E66: 28.42 | F66: 102.42 | G66: 4.35 | H66: 26.67 | I66: 103.47 | J66: 5.24 | K66: 27.03 | L66: 117.38 | M66: 5.32
B67: 19.77 | C67: 88.1 | D67: 5.94 | E67: 19.18 | F67: 87.44 | G67: 6.14 | H67: 17.83 | I67: 87.4 | J67: 5.76 | K67: 18.48 | L67: 87.5 | M67: 5.69
B68: 24.81 | C68: 87.45 | D68: 5.21 | E68: 20.13 | F68: 79.95 | G68: 5.36 | H68: 17.84 | I68: 87.56 | J68: 6.16 | K68: 18.27 | L68: 87.48 | M68: 6.09
B69: 14.47 | C69: 87.5 | D69: 8.22 | E69: 14.7 | F69: 87.46 | G69: 8.22 | H69: 16.84 | I69: 102.55 | J69: 7.51 | K69: 15.38 | L69: 102.52 | M69: 7.93
...

Sheet IDA BRT
B2: Intersecciones IDA BRT
H4: Corridas | I4: Segundos | J4: Velocidad
G5: Tiempo de Viaje | H5: 1 | I5: 2302.4262 | J5: 11.80125
H6: 2 | I6: 2383 | J6: 11.28
H7: 3 | I7: 2418.56 | J7: 11.21
H8: 4 | I8: 2383 | J8: 11.15
B9: Salida Quiroga
B11: Corrida 1 | E11: Corrida 2 | H11: Corrida 3 | K11: Corrida 4
B12: Tiempos de espera | C12: Long. Cola | D12: Velocidad | E12: Tiempos de espera | F12: Long. Cola | G12: Velocidad | H12: Tiempos de espera | I12: Long. Cola | J12: Velocidad | K12: Tiempos de espera | L12: Long. Cola | M12: Velocidad
B13: 9.85 | C13: 42.28 | D13: 9.29 | E13: 11.95 | F13: 34.83 | G13: 8.43 | H13: 13.46 | I13: 57.43 | J13: 7.4 | K13: 10.56 | L13: 42.37 | M13: 8.97
B14: 11.99 | C14: 49.89 | D14: 8.1 | E14: 11.84 | F14: 42.49 | G14: 7.98 | H14: 9.83 | I14: 34.95 | J14: 9.31 | K14: 10.02 | L14: 42.42 | M14: 8.96
B15: 14.11 | C15: 50.01 | D15: 7.55 | E15: 13.42 | F15: 42.53 | G15: 7.79 | H15: 12.19 | I15: 49.83 | J15: 8.01 | K15: 13.5 | L15: 42.35 | M15: 7.85
B16: 14.6 | C16: 42.34 | D16: 7.83 | E16: 14.17 | F16: 42.35 | G16: 7.13 | H16: 7.14 | I16: 27.47 | J16: 11.81 | K16: 13.31 | L16: 42.31 | M16: 7.78
B17: 13.34 | C17: 57.32 | D17: 7.85 | E17: 11.62 | F17: 49.94 | G17: 8.6 | H17: 11.15 | I17: 42.33 | J17: 8.89 | K17: 9.81 | L17: 34.86 | M17: 9.65
B18: 12.55 | C18: 42.39 | D18: 7.88 | E18: 14.33 | F18: 57.34 | G18: 7.43 | H18: 13.46 | I18: 57.36 | J18: 7.42 | K18: 12.29 | L18: 42.49 | M18: 7.74
B19: 18.7 | C19: 57.33 | D19: 6.34 | E19: 17.91 | F19: 49.8 | G19: 6.53 | H19: 12.59 | I19: 34.84 | J19: 8.39 | K19: 13.54 | L19: 49.85 | M19: 7.77
B20: 11.34 | C20: 27.45 | D20: 8.95 | E20: 14.03 | F20: 42.45 | G20: 7.95 | H20: 13.61 | I20: 42.41 | J20: 7.98 | K20: 12.56 | L20: 42.28 | M20: 8.48
B21: 6.62 | C21: 27.44 | D21: 11.86 | E21: 9.16 | F21: 36.05 | G21: 9.79 | H21: 8.55 | I21: 42.3 | J21: 10.24 | K21: 8.23 | L21: 42.14 | M21: 10.35
B22: 13.04 | C22: 49.82 | D22: 7.85 | E22: 11.69 | F22: 42.29 | G22: 8.38 | H22: 11.74 | I22: 34.97 | J22: 8.43 | K22: 9.27 | L22: 35.04 | M22: 10.22
B23: 16.79 | C23: 49.82 | D23: 6.7 | E23: 13.25 | F23: 42.33 | G23: 8.14 | H23: 17.95 | I23: 49.81 | J23: 6.45 | K23: 16.04 | L23: 49.92 | M23: 7.06
B24: 10.64 | C24: 42.36 | D24: 9.22 | E24: 12 | F24: 34.77 | G24: 8.79 | H24: 12.3 | I24: 42.34 | J24: 8.15 | K24: 11.77 | L24: 42.25 | M24: 8.65
... B48: 14.9 | C48: 70.31 | D48: 7.56 | E48: 17.69 | F48: 80.96 | G48: 6.39 | H48: 11 | I48: 70.97 | J48: 9.2 | K48: 13.07 | L48: 59.18 | M48: 8.44
A50: PROMEDIO | B50: =AVERAGE(B13:B48) -> 14.018333 | C50: =AVERAGE(C13:C48) -> 50.563056 | D50: =AVERAGE(D13:D48) -> 7.3991667 | E50: =AVERAGE(E13:E48) -> 14.250556 | F50: =AVERAGE(F13:F48) -> 52.160833 | G50: =AVERAGE(G13:G48) -> 7.2033333 | H50: =AVERAGE(H13:H48) -> 14.094444 | I50: =AVERAGE(I13:I48) -> 50.952778 | ... M50: =AVERAGE(M13:M48) -> 7.6155556
A51: PROMEDIO 4 | B51: =AVERAGE(B50,E50,H50,K50) -> 13.875972 | C51: =AVERAGE(C50,F50,I50,L50) -> 50.439375 | D51: =AVERAGE(D50,G50,J50,M50) -> 7.4043056
B53: San Juanito
B55: Corrida 1 | E55: Corrida 2 | H55: Corrida 3 | K55: Corrida 4
B56: Tiempos de espera | C56: Long. Cola | D56: Velocidad | E56: Tiempos de espera | F56: Long. Cola | G56: Velocidad | H56: Tiempos de espera | I56: Long. Cola | J56: Velocidad | K56: Tiempos de espera | L56: Long. Cola | M56: Velocidad
A57: principal | B57: 16.34 | C57: 102.94 | D57: 7.69 | E57: 16.67 | F57: 110.25 | G57: 7.69 | H57: 16.38 | I57: 102.82 | J57: 7.69 | K57: 16.21 | L57: 102.88 | M57: 7.57
B58: 28.99 | C58: 141.1 | D58: 5.73 | E58: 29.58 | F58: 148.59 | G58: 5.87 | H58: 27.93 | I58: 132.45 | J58: 5.82 | K58: 27.15 | L58: 148.14 | M58: 5.92
B59: 32.71 | C59: 117.38 | D59: 5.5 | E59: 28.84 | F59: 118.66 | G59: 5.69 | H59: 32.72 | I59: 117.28 | J59: 5.45 | K59: 37.8 | L59: 132.27 | M59: 4.94
B60: 32.99 | C60: 117.88 | D60: 5.76 | E60: 29.67 | F60: 87.37 | G60: 6.28 | H60: 31.81 | I60: 103.15 | J60: 5.84 | K60: 36.29 | L60: 109.74 | M60: 5.47
B61: 43.64 | C61: 117.77 | D61: 4.76 | E61: 40.07 | F61: 95.17 | G61: 4.97 | H61: 44.99 | I61: 110.46 | J61: 4.28 | K61: 38.26 | L61: 87.7 | M61: 5.14
B62: 18.36 | C62: 64.7 | D62: 7.46 | E62: 19.47 | F62: 64.85 | G62: 7.34 | H62: 29.8 | I62: 80.35 | J62: 5.86 | K62: 19.58 | L62: 57.15 | M62: 7.55
B63: 26.04 | C63: 80.02 | D63: 6.05 | E63: 29.5 | F63: 80.36 | G63: 5.95 | H63: 20.82 | I63: 49.72 | J63: 7 | K63: 25.56 | L63: 72.75 | M63: 6.18
B64: 18.36 | C64: 64.7 | D64: 7.46 | E64: 18.36 | F64: 64.7 | G64: 7.46 | H64: 18.36 | I64: 64.7 | J64: 7.46 | K64: 13.55 | L64: 19.68 | M64: 8.81
B65: 18.85 | C65: 82.23 | D65: 7.94 | E65: 18.45 | F65: 95.3 | G65: 8.08 | H65: 17.93 | I65: 87.5 | J65: 7.98 | K65: 18.2 | L65: 87.81 | M65: 8.06
B66: 14.78 | C66: 102.46 | D66: 7.89 | E66: 21.41 | F66: 87.3 | G66: 6.86 | H66: 17.13 | I66: 79.75 | J66: 7.4 | K66: 17.95 | L66: 96.12 | M66: 7.62
B67: 12.96 | C67: 50.55 | D67: 8.42 | E67: 21 | F67: 96.27 | G67: 6.65 | H67: 21.9 | I67: 95.12 | J67: 6.33 | K67: 17.76 | L67: 94.97 | M67: 7.42
B68: 43.27 | C68: 163.06 | D68: 3.94 | E68: 42.07 | F68: 155.75 | G68: 3.84 | H68: 41.88 | I68: 140.54 | J68: 4.18 | K68: 37.66 | L68: 140.57 | M68: 4.05
B69: 17.21 | C69: 103.08 | D69: 7.67 | E69: 16.73 | F69: 102.45 | G69: 7.74 | H69: 16.93 | I69: 110.47 | J69: 7.8 | K69: 18.06 | L69: 103.15 | M69: 7.53
...

Sheet VUELTA BRT
B2: Intersecciones VUELTA BRT
H4: Corridas | I4: Segundos | J4: Velocidad
G5: Tiempo de Viaje | H5: 1 | I5: 2321.35 | J5: 12.19
H6: 2
H7: 3
H8: 4
B9: Salida Quiroga
B11: Corrida 1 | E11: Corrida 2 | H11: Corrida 3 | K11: Corrida 4
B12: Tiempos de espera | C12: Long. Cola | D12: Velocidad | E12: Tiempos de espera | F12: Long. Cola | G12: Velocidad | H12: Tiempos de espera | I12: Long. Cola | J12: Velocidad | K12: Tiempos de espera | L12: Long. Cola | M12: Velocidad
B13: 22.32 | C13: 102.44 | D13: 6.23 | E13: 25.35 | F13: 125.48 | G13: 5.56 | H13: 26.13 | I13: 94.95 | J13: 5.61 | K13: 26.24 | L13: 110.14 | M13: 5.53
B14: 15.54 | C14: 50.23 | D14: 7.9 | E14: 16.51 | F14: 65.34 | G14: 7.61 | H14: 16.59 | I14: 65.36 | J14: 7.76 | K14: 16.13 | L14: 57.36 | M14: 7.76
B15: 14.9 | C15: 102.43 | D15: 7.92 | E15: 15.37 | F15: 87.35 | G15: 7.81 | H15: 15.67 | I15: 87.5 | J15: 7.85 | K15: 15.28 | L15: 95.6 | M15: 8.06
B16: 14.58 | C16: 72.42 | D16: 7.11 | E16: 12.6 | F16: 57.92 | G16: 8.23 | H16: 18.64 | I16: 65.66 | J16: 6.5 | K16: 16 | L16: 65.08 | M16: 7.18
B17: 20.17 | C17: 163.52 | D17: 6.26 | E17: 20.13 | F17: 147.49 | G17: 6.45 | H17: 18.93 | I17: 132.33 | J17: 6.82 | K17: 17.82 | L17: 140.04 | M17: 6.65
B18: 16.15 | C18: 102.35 | D18: 7.89 | E18: 18.06 | F18: 110.31 | G18: 7.45 | H18: 16.78 | I18: 110.58 | J18: 7.75 | K18: 17.18 | L18: 125.25 | M18: 7.59
B19: 22.57 | C19: 156.48 | D19: 5.82 | E19: 17.83 | F19: 126.62 | G19: 6.53 | H19: 18.52 | I19: 163.21 | J19: 6.59 | K19: 19.08 | L19: 170.72 | M19: 6.7
B20: 10.24 | C20: 118.19 | D20: 8.84 | E20: 8.75 | F20: 102.97 | G20: 10.12 | H20: 8.1 | I20: 110.78 | J20: 10.07 | K20: 9.36 | L20: 95.59 | M20: 9.27
B21: 11.72 | C21: 133.26 | D21: 7.78 | E21: 8.12 | F21: 102.46 | G21: 9.67 | H21: 13.2 | I21: 125.75 | J21: 6.99 | K21: 9.16 | L21: 110.65 | M21: 9.21
B22: 18.5 | C22: 95.43 | D22: 6.96 | E22: 22.24 | F22: 95.43 | G22: 6.46 | H22: 21.9 | I22: 96.64 | J22: 6.1 | K22: 17.85 | L22: 81.28 | M22: 7.29
B23: 16.96 | C23: 111.25 | D23: 7.19 | E23: 14.57 | F23: 66.41 | G23: 8.17 | H23: 15.5 | I23: 58.7 | J23: 7.85 | K23: 18 | L23: 103.64 | M23: 6.87
B24: 8.46 | C24: 72.53 | D24: 10.15 | E24: 7.32 | F24: 72.59 | G24: 10.75 | H24: 6.31 | I24: 94.99 | J24: 11.91 | K24: 8.75 | L24: 64.87 | M24: 9.96
... B48: 30.74 | C48: 118.08 | D48: 4.14 | E48: 39.33 | F48: 109.59 | G48: 3.28 | H48: 34.11 | I48: 138.98 | J48: 3.68 | K48: 19.77 | L48: 110.25 | M48: 5.87
A50: PROMEDIO | B50: =AVERAGE(B13:B48) -> 17.8475 | C50: =AVERAGE(C13:C48) -> 101.23167 | D50: =AVERAGE(D13:D48) -> 7.1013889 | E50: =AVERAGE(E13:E48) -> 17.720278 | F50: =AVERAGE(F13:F48) -> 97.472222 | G50: =AVERAGE(G13:G48) -> 7.4583333 | H50: =AVERAGE(H13:H48) -> 17.443611 | I50: =AVERAGE(I13:I48) -> 96.744722 | ... M50: =AVERAGE(M13:M48) -> 7.2361111
A51: PROMEDIO 4 | B51: =AVERAGE(B50,E50,H50,K50) -> 17.593264 | C51: =AVERAGE(C50,F50,I50,L50) -> 98.302222 | D51: =AVERAGE(D50,G50,J50,M50) -> 7.2677083
B53: San Juanito
B55: Corrida 1 | E55: Corrida 2 | H55: Corrida 3 | K55: Corrida 4
B56: Tiempos de espera | C56: Long. Cola | D56: Velocidad | E56: Tiempos de espera | F56: Long. Cola | G56: Velocidad | H56: Tiempos de espera | I56: Long. Cola | J56: Velocidad | K56: Tiempos de espera | L56: Long. Cola | M56: Velocidad
A57: principal | B57: 17.3 | C57: 72.52 | D57: 7.27 | E57: 18.26 | F57: 87.59 | G57: 7.47 | H57: 17.19 | I57: 80.09 | J57: 7.39 | K57: 16.49 | L57: 80.05 | M57: 7.45
B58: 21.7 | C58: 117.53 | D58: 6.94 | E58: 23.12 | F58: 103.98 | G58: 6.43 | H58: 16.73 | I58: 96.04 | J58: 8 | K58: 17.98 | L58: 88.48 | M58: 7.67
B59: 24.94 | C59: 119.33 | D59: 6.46 | E59: 21.89 | F59: 111.18 | G59: 6.65 | H59: 21.93 | I59: 110.12 | J59: 6.98 | K59: 22.9 | L59: 102.71 | M59: 6.92
B60: 25.9 | C60: 102.49 | D60: 5.98 | E60: 28.89 | F60: 102.49 | G60: 6.28 | H60: 29.45 | I60: 140 | J60: 5.85 | K60: 27.37 | L60: 102.49 | M60: 5.91
B61: 24.86 | C61: 117.49 | D61: 6.7 | E61: 21.11 | F61: 102.59 | G61: 7.37 | H61: 22.06 | I61: 102.57 | J61: 7.01 | K61: 23.49 | L61: 110.1 | M61: 6.7
B62: 27.08 | C62: 102.49 | D62: 6.55 | E62: 24.75 | F62: 96.06 | G62: 6.2 | H62: 28.07 | I62: 102.49 | J62: 6.03 | K62: 22.92 | L62: 95.04 | M62: 6.83
B63: 19.56 | C63: 88.8 | D63: 7.99 | E63: 23.03 | F63: 102.55 | G63: 7.29 | H63: 19.26 | I63: 88.94 | J63: 8.06 | K63: 25.26 | L63: 110.57 | M63: 6.86
B64: 29.19 | C64: 102.49 | D64: 5.92 | E64: 24.13 | F64: 118.69 | G64: 6.56 | H64: 24.31 | I64: 102.53 | J64: 6.01 | K64: 23.53 | L64: 102.68 | M64: 6.81
B65: 29.34 | C65: 109.97 | D65: 6.15 | E65: 29.72 | F65: 109.97 | G65: 5.72 | H65: 27.44 | I65: 109.97 | J65: 6.54 | K65: 26.82 | L65: 109.97 | M65: 6.02
B66: 26.66 | C66: 102.49 | D66: 5.86 | E66: 18.33 | F66: 96.12 | G66: 7.1 | H66: 19.19 | I66: 79.98 | J66: 7.33 | K66: 21.42 | L66: 102.49 | M66: 6.56
B67: 19.25 | C67: 109.97 | D67: 7.18 | E67: 16.86 | F67: 111.01 | G67: 7.37 | H67: 17.2 | I67: 117.52 | J67: 7.7 | K67: 16.25 | L67: 117.52 | M67: 7.92
B68: 15.1 | C68: 72.55 | D68: 7.86 | E68: 20.54 | F68: 95.12 | G68: 6.65 | H68: 18.5 | I68: 96.44 | J68: 7.29 | K68: 15.26 | L68: 95.18 | M68: 7.4
B69: 10.61 | C69: 64.96 | D69: 10.78 | E69: 10.23 | F69: 80.04 | G69: 10.5 | H69: 11.3 | I69: 72.49 | J69: 9.69 | K69: 10.06 | L69: 72.26 | M69: 10.87
...

Sheet IDA BRT TRANS
B2: Intersecciones IDA BRT TRANS
H4: Corridas | I4: Segundos | J4: Velocidad
G5: Tiempo de Viaje | H5: 1
H6: 2
H7: 3
H8: 4
B9: Salida Quiroga
B11: Corrida 1 | E11: Corrida 2 | H11: Corrida 3 | K11: Corrida 4
B12: Tiempos de espera | C12: Long. Cola | D12: Velocidad | E12: Tiempos de espera | F12: Long. Cola | G12: Velocidad | H12: Tiempos de espera | I12: Long. Cola | J12: Velocidad | K12: Tiempos de espera | L12: Long. Cola | M12: Velocidad
B13: 11.12 | C13: 42.42 | D13: 8.85 | E13: 11.57 | F13: 49.9 | G13: 8.73 | H13: 10.05 | I13: 34.85 | J13: 9.86 | K13: 11.66 | L13: 41.33 | M13: 8.36
B14: 12.27 | C14: 57.45 | D14: 8.09 | E14: 9.96 | F14: 42.47 | G14: 8.66 | H14: 10.73 | I14: 49.9 | J14: 8.89 | K14: 10.4 | L14: 34.92 | M14: 8.8
B15: 12.27 | C15: 49.87 | D15: 8.41 | E15: 11.35 | F15: 42.34 | G15: 8.77 | H15: 13.54 | I15: 43.81 | J15: 7.6 | K15: 16.12 | L15: 42.52 | M15: 7.19
B16: 12.81 | C16: 41.29 | D16: 7.99 | E16: 13.99 | F16: 48.8 | G16: 7.45 | H16: 13.24 | I16: 42.53 | J16: 7.9 | K16: 13.29 | L16: 42.44 | M16: 7.71
B17: 7.83 | C17: 34.77 | D17: 11 | E17: 10.53 | F17: 49.94 | G17: 9.3 | H17: 10 | I17: 43.55 | J17: 8.79 | K17: 10.87 | L17: 34.79 | M17: 11.22
B18: 8.81 | C18: 34.86 | D18: 9.97 | E18: 10.18 | F18: 42.4 | G18: 8.77 | H18: 15.15 | I18: 57.45 | J18: 6.5 | K18: 11.72 | L18: 57.42 | M18: 8.24
B19: 12.49 | C19: 42.28 | D19: 8.45 | E19: 15.19 | F19: 49.36 | G19: 7.43 | H19: 13.53 | I19: 42.44 | J19: 7.82 | K19: 11.51 | L19: 42.39 | M19: 8.99
B20: 11.19 | C20: 41.3 | D20: 8.77 | E20: 11.87 | F20: 49.91 | G20: 8.04 | H20: 13.93 | I20: 42.27 | J20: 7.5 | K20: 13.13 | L20: 42.35 | M20: 8.19
B21: 13.95 | C21: 34.63 | D21: 5.83 | E21: 13.66 | F21: 57.39 | G21: 9.72 | H21: 8.26 | I21: 42.33 | J21: 5.83 | K21: 10.33 | L21: 42.36 | M21: 5.83
B22: 13.31 | C22: 35.89 | D22: 7.85 | E22: 10.03 | F22: 34.93 | G22: 9.43 | H22: 13.83 | I22: 49.87 | J22: 7.51 | K22: 11.82 | L22: 43.62 | M22: 8.15
B23: 14.23 | C23: 43.12 | D23: 7.64 | E23: 15.7 | F23: 49.94 | G23: 7.11 | H23: 14.31 | I23: 42.35 | J23: 7.75 | K23: 14.65 | L23: 42.37 | M23: 7.5
B24: 9.74 | C24: 42.36 | D24: 9.69 | E24: 10.15 | F24: 42.33 | G24: 9.02 | H24: 10.21 | I24: 34.87 | J24: 9.75 | K24: 12.87 | L24: 42.26 | M24: 7.83
... B48: 11.63 | C48: 42.2 | D48: 8.87 | E48: 13.72 | F48: 49.64 | G48: 7.72 | H48: 15.88 | I48: 93.07 | J48: 7.08 | K48: 14.71 | L48: 57.33 | M48: 7.62
A50: PROMEDIO | B50: =AVERAGE(B13:B48) -> 13.989167 | C50: =AVERAGE(C13:C48) -> 49.872222 | D50: =AVERAGE(D13:D48) -> 7.375 | E50: =AVERAGE(E13:E48) -> 13.816111 | F50: =AVERAGE(F13:F48) -> 51.581667 | G50: =AVERAGE(G13:G48) -> 7.5075 | H50: =AVERAGE(H13:H48) -> 13.938333 | I50: =AVERAGE(I13:I48) -> 49.674722 | ... M50: =AVERAGE(M13:M48) -> 7.3905556
A51: PROMEDIO 4 | B51: =AVERAGE(B50,E50,H50,K50) -> 13.903889 | C51: =AVERAGE(C50,F50,I50,L50) -> 50.128542 | D51: =AVERAGE(D50,G50,J50,M50) -> 7.3726389
B53: San Juanito
B55: Corrida 1 | E55: Corrida 2 | H55: Corrida 3 | K55: Corrida 4
B56: Tiempos de espera | C56: Long. Cola | D56: Velocidad | E56: Tiempos de espera | F56: Long. Cola | G56: Velocidad | H56: Tiempos de espera | I56: Long. Cola | J56: Velocidad | K56: Tiempos de espera | L56: Long. Cola | M56: Velocidad
A57: principal | B57: 17.38 | C57: 110.07 | D57: 7.44 | E57: 17.32 | F57: 117.89 | G57: 7.6 | H57: 16.18 | I57: 95.18 | J57: 7.86 | K57: 17.03 | L57: 111.67 | M57: 7.4
B58: 28.96 | C58: 140.35 | D58: 5.59 | E58: 25.44 | F58: 132.76 | G58: 5.86 | H58: 27.91 | I58: 132.84 | J58: 5.89 | K58: 27.15 | L58: 140.18 | M58: 5.69
B59: 28.33 | C59: 117.25 | D59: 5.93 | E59: 30.32 | F59: 96.25 | G59: 5.68 | H59: 34.3 | I59: 147.64 | J59: 5.01 | K59: 29.47 | L59: 147.27 | M59: 5.71
B60: 38.49 | C60: 132.55 | D60: 5.09 | E60: 32.04 | F60: 94.98 | G60: 5.75 | H60: 33.4 | I60: 102.96 | J60: 5.78 | K60: 36.1 | L60: 102.34 | M60: 5.19
B61: 42.86 | C61: 125.49 | D61: 5.01 | E61: 38.51 | F61: 95.75 | G61: 5.23 | H61: 40.61 | I61: 86.55 | J61: 4.73 | K61: 42.72 | L61: 103.45 | M61: 4.78
B62: 27.15 | C62: 94.83 | D62: 6.03 | E62: 27.25 | F62: 80.14 | G62: 5.84 | H62: 18.81 | I62: 42.19 | J62: 6.96 | K62: 17.37 | L62: 42.19 | M62: 7.88
B63: 24.05 | C63: 64.84 | D63: 6.51 | E63: 34.85 | F63: 72.76 | G63: 6.4 | H63: 24.82 | I63: 57.36 | J63: 5.83 | K63: 23.19 | L63: 50.11 | M63: 6.25
B64: 13.47 | C64: 27.22 | D64: 8.9 | E64: 28.67 | F64: 19.73 | G64: 9.93 | H64: 28.67 | I64: 34.67 | J64: 9.63 | K64: 7.99 | L64: 20.64 | M64: 9.96
B65: 19.45 | C65: 96.25 | D65: 7.75 | E65: 19.19 | F65: 88.64 | G65: 7.91 | H65: 18.43 | I65: 103.84 | J65: 7.73 | K65: 19.36 | L65: 103.84 | M65: 7.9
B66: 17.26 | C66: 94.67 | D66: 7.57 | E66: 13.41 | F66: 72.7 | G66: 8.18 | H66: 17.77 | I66: 103.08 | J66: 7.69 | K66: 20.95 | L66: 117.23 | M66: 6.65
B67: 19.43 | C67: 109.86 | D67: 6.75 | E67: 17.32 | F67: 79.99 | G67: 7.36 | H67: 20.31 | I67: 124.84 | J67: 7.09 | K67: 27.45 | L67: 124.84 | M67: 6.31
B68: 36.47 | C68: 147.78 | D68: 4.08 | E68: 37.18 | F68: 155.53 | G68: 4.17 | H68: 38.11 | I68: 109.66 | J68: 4.3 | K68: 46.57 | L68: 124.82 | M68: 4.16
B69: 17.47 | C69: 110.45 | D69: 7.68 | E69: 17.05 | F69: 118.28 | G69: 7.65 | H69: 18.12 | I69: 95.22 | J69: 7.54 | K69: 18.21 | L69: 125.07 | M69: 7.4
...

Sheet VUELTA BRT TRANS
B2: Intersecciones VUELTA BRT TRANS
H4: Corridas | I4: Segundos | J4: Velocidad
G5: Tiempo de Viaje | H5: 1
H6: 2
H7: 3
H8: 4
B9: Salida Quiroga
B11: Corrida 1 | E11: Corrida 2 | H11: Corrida 3 | K11: Corrida 4
B12: Tiempos de espera | C12: Long. Cola | D12: Velocidad | E12: Tiempos de espera | F12: Long. Cola | G12: Velocidad | H12: Tiempos de espera | I12: Long. Cola | J12: Velocidad | K12: Tiempos de espera | L12: Long. Cola | M12: Velocidad
B13: 23.9 | C13: 110.64 | D13: 5.9 | E13: 26.22 | F13: 117.89 | G13: 5.49 | H13: 23.12 | I13: 94.96 | J13: 5.98 | K13: 22.63 | L13: 94.99 | M13: 6.14
B14: 16.44 | C14: 50.11 | D14: 7.86 | E14: 15.28 | F14: 50.05 | G14: 8.1 | H14: 18.79 | I14: 80.4 | J14: 6.94 | K14: 16.04 | L14: 65.22 | M14: 7.6
B15: 14.76 | C15: 103.09 | D15: 7.88 | E15: 16.16 | F15: 95.73 | G15: 7.58 | H15: 17.07 | I15: 107.93 | J15: 7.45 | K15: 12.05 | L15: 72.7 | M15: 8.96
B16: 13.82 | C16: 57.48 | D16: 7.81 | E16: 13.81 | F16: 73.41 | G16: 7.76 | H16: 19.32 | I16: 117.76 | J16: 6.2 | K16: 14.35 | L16: 57.47 | M16: 7.69
B17: 21.51 | C17: 147.74 | D17: 6.1 | E17: 21.03 | F17: 155.01 | G17: 6.04 | H17: 20.9 | I17: 140.31 | J17: 6.17 | K17: 23.89 | L17: 155.21 | M17: 5.6
B18: 15.6 | C18: 110.45 | D18: 7.99 | E18: 19.11 | F18: 125.52 | G18: 7.16 | H18: 15.15 | I18: 110.65 | J18: 8.11 | K18: 16.04 | L18: 117.85 | M18: 7.73
B19: 17.61 | C19: 103.02 | D19: 6.8 | E19: 19.76 | F19: 142.17 | G19: 6.24 | H19: 16.6 | I19: 121.94 | J19: 7.33 | K19: 13.62 | L19: 95.53 | M19: 8.34
B20: 11.21 | C20: 110.51 | D20: 8.8 | E20: 10.72 | F20: 102.7 | G20: 8.55 | H20: 10.05 | I20: 102.57 | J20: 9.33 | K20: 8.81 | L20: 102.7 | M20: 10.1
B21: 8.42 | C21: 118.02 | D21: 9.66 | E21: 10.33 | F21: 117.98 | G21: 8.3 | H21: 9.05 | I21: 102.42 | J21: 9.12 | K21: 6.34 | L21: 110.44 | M21: 11.07
B22: 17.51 | C22: 96.82 | D22: 7.13 | E22: 19.41 | F22: 95.82 | G22: 6.95 | H22: 21.51 | I22: 96.67 | J22: 6.54 | K22: 21.72 | L22: 96.43 | M22: 6.52
B23: 17.13 | C23: 72.81 | D23: 7.11 | E23: 14.78 | F23: 66.8 | G23: 8.14 | H23: 20.76 | I23: 155.46 | J23: 6.01 | K23: 19.44 | L23: 110.35 | M23: 6.6
B24: 10.49 | C24: 132.73 | D24: 9.1 | E24: 9.4 | F24: 110.12 | G24: 9.86 | H24: 10.05 | I24: 117.97 | J24: 9.46 | K24: 6.47 | L24: 42.49 | M24: 11.57
... B48: 36.82 | C48: 112.42 | D48: 3.56 | E48: 23.51 | F48: 88.26 | G48: 5.5 | H48: 19.56 | I48: 102.79 | J48: 5.92 | K48: 14.07 | L48: 94.89 | M48: 7.27
A50: PROMEDIO | B50: =AVERAGE(B13:B48) -> 17.429722 | C50: =AVERAGE(C13:C48) -> 95.647778 | D50: =AVERAGE(D13:D48) -> 7.3455556 | E50: =AVERAGE(E13:E48) -> 17.539444 | F50: =AVERAGE(F13:F48) -> 101.74833 | G50: =AVERAGE(G13:G48) -> 7.2802778 | H50: =AVERAGE(H13:H48) -> 17.731944 | I50: =AVERAGE(I13:I48) -> 102.99083 | ... M50: =AVERAGE(M13:M48) -> 7.6027778
A51: PROMEDIO 4 | B51: =AVERAGE(B50,E50,H50,K50) -> 17.361736 | C51: =AVERAGE(C50,F50,I50,L50) -> 99.133194 | D51: =AVERAGE(D50,G50,J50,M50) -> 7.3414583
B53: San Juanito
B55: Corrida 1 | E55: Corrida 2 | H55: Corrida 3 | K55: Corrida 4
B56: Tiempos de espera | C56: Long. Cola | D56: Velocidad | E56: Tiempos de espera | F56: Long. Cola | G56: Velocidad | H56: Tiempos de espera | I56: Long. Cola | J56: Velocidad | K56: Tiempos de espera | L56: Long. Cola | M56: Velocidad
A57: principal | B57: 22.75 | C57: 87.42 | D57: 5.23 | E57: 23.7 | F57: 87.46 | G57: 5.46 | H57: 21.74 | I57: 87.48 | J57: 5.53 | K57: 21.57 | L57: 87.46 | M57: 5.7
B58: 21.7 | C58: 87.48 | D58: 5.8 | E58: 26.15 | F58: 87.49 | G58: 5.21 | H58: 20.47 | I58: 79.86 | J58: 5.86 | K58: 20.32 | L58: 79.97 | M58: 6.44
B59: 24.49 | C59: 95.51 | D59: 5.72 | E59: 23.17 | F59: 94.95 | G59: 5.7 | H59: 20.52 | I59: 79.9 | J59: 6.34 | K59: 26 | L59: 80.95 | M59: 5.38
B60: 31.13 | C60: 124.94 | D60: 6.78 | E60: 35.56 | F60: 132.45 | G60: 6.78 | H60: 31.53 | I60: 109.9 | J60: 6.78 | K60: 36.1 | L60: 132.48 | M60: 4.55
B61: 26.41 | C61: 102.43 | D61: 5.27 | E61: 25.6 | F61: 94.97 | G61: 5.12 | H61: 23.34 | I61: 94.86 | J61: 5.2 | K61: 22.49 | L61: 88.65 | M61: 5.71
B62: 18.79 | C62: 132.51 | D62: 6.78 | E62: 28.84 | F62: 102.49 | G62: 6.78 | H62: 32.75 | I62: 117.44 | J62: 6.78 | K62: 32.16 | L62: 110.12 | M62: 6.78
B63: 19.17 | C63: 72.51 | D63: 6.22 | E63: 22.56 | F63: 72.4 | G63: 5.82 | H63: 21.68 | I63: 72.4 | J63: 5.76 | K63: 25.1 | L63: 72.46 | M63: 5.96
B64: 27.28 | C64: 88.02 | D64: 5.91 | E64: 18.79 | F64: 117.51 | G64: 5.13 | H64: 18.79 | I64: 111.01 | J64: 5.32 | K64: 18.79 | L64: 96.42 | M64: 6.78
B65: 15.83 | C65: 109.91 | D65: 6.22 | E65: 15.83 | F65: 117.4 | G65: 6.22 | H65: 15.83 | I65: 139.96 | J65: 6.22 | K65: 15.83 | L65: 154.96 | M65: 6.22
B66: 26.35 | C66: 87.41 | D66: 5.28 | E66: 24.47 | F66: 94.85 | G66: 8.15 | H66: 18.79 | I66: 117.44 | J66: 8.15 | K66: 18.79 | L66: 124.89 | M66: 8.15
B67: 18.8 | C67: 80.06 | D67: 5.74 | E67: 15.07 | F67: 79.86 | G67: 6.79 | H67: 17.77 | I67: 87.43 | J67: 6.11 | K67: 19.75 | L67: 94.98 | M67: 5.94
B68: 19.49 | C68: 94.93 | D68: 5.93 | E68: 20.79 | F68: 79.92 | G68: 5.83 | H68: 20.66 | I68: 79.95 | J68: 5.37 | K68: 20.68 | L68: 88.93 | M68: 5.44
B69: 14.63 | C69: 87.46 | D69: 8.15 | E69: 15.59 | F69: 94.93 | G69: 7.96 | H69: 13.55 | I69: 87.43 | J69: 8.29 | K69: 14.05 | L69: 87.43 | M69: 8.24
...

Sheet emisiones
B2: Datos de 1 vehiculo con todos los parametros de SUMO | G2: 1 automovil | H2: en word
G3: 1 camion | H3: en word
G4: 1 brt | H4: abajo esta
A5: Esto para 1 vehiculo:
B7: CO | C7: 16.8 | D7: g/km
B8: CO2 | C8: 4.33 | D8: kg
B9: Nox | C9: 1.05 | D9: g
B10: PMx | C10: 0.084 | D10: g
A12: Para 26 mil vehiculos aproximadamente: | F12: 540 transportes
B13: CO | C13: 109.2 | D13: kg | F13: CO | G13: 4.75 | H13: kg
B14: CO2 | C14: 65520 | D14: kg | F14: CO2 | G14: 2563 | H14: kg
B15: Nox | C15: 21.84 | D15: kg | F15: Nox | G15: 0.7314 | H15: kg
B16: PMx | C16: 5.46 | D16: kg | F16: PMx | G16: 0.3806 | H16: kg
F18: 1 BRT(MERCEDES,diesel) | J18: 1BRT/ 21 km/vel 40/21 paradas
F19: CO | G19: 1 | H19: g/km | J19: 21 | K19: gr
F20: CO2 | G20: 800 | H20: g/km | J20: 16100 | K20: gr
F21: Nox | G21: 5 | H21: g/km | J21: 75 | K21: gr
F22: PMx | G22: 0.05 | H22: g/km | J22: =G22*21 -> 1.05 | K22: gr
